2018-03-12 09:58:06,283 ERROR: Exception on / [GET] [in /home/train/anaconda2/envs/flask/lib/python2.7/site-packages/flask/app.py:1560]
Traceback (most recent call last):
  File "/home/train/anaconda2/envs/flask/lib/python2.7/site-packages/flask/app.py", line 1982, in wsgi_app
    response = self.full_dispatch_request()
  File "/home/train/anaconda2/envs/flask/lib/python2.7/site-packages/flask/app.py", line 1614, in full_dispatch_request
    rv = self.handle_user_exception(e)
  File "/home/train/anaconda2/envs/flask/lib/python2.7/site-packages/flask/app.py", line 1517, in handle_user_exception
    reraise(exc_type, exc_value, tb)
  File "/home/train/anaconda2/envs/flask/lib/python2.7/site-packages/flask/app.py", line 1610, in full_dispatch_request
    rv = self.preprocess_request()
  File "/home/train/anaconda2/envs/flask/lib/python2.7/site-packages/flask/app.py", line 1831, in preprocess_request
    rv = func()
  File "/media/store/myImplement/my_graduation_paper/obm/app/main/routes.py", line 16, in before_request
    if current_user.is_authenticated:
  File "/home/train/anaconda2/envs/flask/lib/python2.7/site-packages/werkzeug/local.py", line 347, in __getattr__
    return getattr(self._get_current_object(), name)
  File "/home/train/anaconda2/envs/flask/lib/python2.7/site-packages/werkzeug/local.py", line 306, in _get_current_object
    return self.__local()
  File "/home/train/anaconda2/envs/flask/lib/python2.7/site-packages/flask_login/utils.py", line 26, in <lambda>
    current_user = LocalProxy(lambda: _get_user())
  File "/home/train/anaconda2/envs/flask/lib/python2.7/site-packages/flask_login/utils.py", line 302, in _get_user
    current_app.login_manager._load_user()
  File "/home/train/anaconda2/envs/flask/lib/python2.7/site-packages/flask_login/login_manager.py", line 317, in _load_user
    return self.reload_user()
  File "/home/train/anaconda2/envs/flask/lib/python2.7/site-packages/flask_login/login_manager.py", line 279, in reload_user
    user = self.user_callback(user_id)
  File "/media/store/myImplement/my_graduation_paper/obm/app/models.py", line 120, in load_user
    return User.query.get(int(id))
  File "/home/train/anaconda2/envs/flask/lib/python2.7/site-packages/flask_sqlalchemy/__init__.py", line 512, in __get__
    mapper = orm.class_mapper(type)
  File "/home/train/anaconda2/envs/flask/lib/python2.7/site-packages/sqlalchemy/orm/base.py", line 421, in class_mapper
    mapper = _inspect_mapped_class(class_, configure=configure)
  File "/home/train/anaconda2/envs/flask/lib/python2.7/site-packages/sqlalchemy/orm/base.py", line 400, in _inspect_mapped_class
    mapper._configure_all()
  File "/home/train/anaconda2/envs/flask/lib/python2.7/site-packages/sqlalchemy/orm/mapper.py", line 1222, in _configure_all
    configure_mappers()
  File "/home/train/anaconda2/envs/flask/lib/python2.7/site-packages/sqlalchemy/orm/mapper.py", line 2869, in configure_mappers
    raise e
InvalidRequestError: One or more mappers failed to initialize - can't proceed with initialization of other mappers. Triggering mapper: 'Mapper|User|user'. Original exception was: When initializing mapper Mapper|User|user, expression 'Post' failed to locate a name ("name 'Post' is not defined"). If this is a class name, consider adding this relationship() to the <class 'app.models.User'> class after both dependent classes have been defined.
2018-03-12 09:58:06,466 ERROR: Exception on / [GET] [in /home/train/anaconda2/envs/flask/lib/python2.7/site-packages/flask/app.py:1560]
Traceback (most recent call last):
  File "/home/train/anaconda2/envs/flask/lib/python2.7/site-packages/flask/app.py", line 1982, in wsgi_app
    response = self.full_dispatch_request()
  File "/home/train/anaconda2/envs/flask/lib/python2.7/site-packages/flask/app.py", line 1614, in full_dispatch_request
    rv = self.handle_user_exception(e)
  File "/home/train/anaconda2/envs/flask/lib/python2.7/site-packages/flask/app.py", line 1517, in handle_user_exception
    reraise(exc_type, exc_value, tb)
  File "/home/train/anaconda2/envs/flask/lib/python2.7/site-packages/flask/app.py", line 1610, in full_dispatch_request
    rv = self.preprocess_request()
  File "/home/train/anaconda2/envs/flask/lib/python2.7/site-packages/flask/app.py", line 1831, in preprocess_request
    rv = func()
  File "/media/store/myImplement/my_graduation_paper/obm/app/main/routes.py", line 16, in before_request
    if current_user.is_authenticated:
  File "/home/train/anaconda2/envs/flask/lib/python2.7/site-packages/werkzeug/local.py", line 347, in __getattr__
    return getattr(self._get_current_object(), name)
  File "/home/train/anaconda2/envs/flask/lib/python2.7/site-packages/werkzeug/local.py", line 306, in _get_current_object
    return self.__local()
  File "/home/train/anaconda2/envs/flask/lib/python2.7/site-packages/flask_login/utils.py", line 26, in <lambda>
    current_user = LocalProxy(lambda: _get_user())
  File "/home/train/anaconda2/envs/flask/lib/python2.7/site-packages/flask_login/utils.py", line 302, in _get_user
    current_app.login_manager._load_user()
  File "/home/train/anaconda2/envs/flask/lib/python2.7/site-packages/flask_login/login_manager.py", line 317, in _load_user
    return self.reload_user()
  File "/home/train/anaconda2/envs/flask/lib/python2.7/site-packages/flask_login/login_manager.py", line 279, in reload_user
    user = self.user_callback(user_id)
  File "/media/store/myImplement/my_graduation_paper/obm/app/models.py", line 120, in load_user
    return User.query.get(int(id))
  File "/home/train/anaconda2/envs/flask/lib/python2.7/site-packages/flask_sqlalchemy/__init__.py", line 512, in __get__
    mapper = orm.class_mapper(type)
  File "/home/train/anaconda2/envs/flask/lib/python2.7/site-packages/sqlalchemy/orm/base.py", line 421, in class_mapper
    mapper = _inspect_mapped_class(class_, configure=configure)
  File "/home/train/anaconda2/envs/flask/lib/python2.7/site-packages/sqlalchemy/orm/base.py", line 400, in _inspect_mapped_class
    mapper._configure_all()
  File "/home/train/anaconda2/envs/flask/lib/python2.7/site-packages/sqlalchemy/orm/mapper.py", line 1222, in _configure_all
    configure_mappers()
  File "/home/train/anaconda2/envs/flask/lib/python2.7/site-packages/sqlalchemy/orm/mapper.py", line 2869, in configure_mappers
    raise e
InvalidRequestError: One or more mappers failed to initialize - can't proceed with initialization of other mappers. Triggering mapper: 'Mapper|User|user'. Original exception was: When initializing mapper Mapper|User|user, expression 'Post' failed to locate a name ("name 'Post' is not defined"). If this is a class name, consider adding this relationship() to the <class 'app.models.User'> class after both dependent classes have been defined.
2018-03-12 09:58:06,647 ERROR: Exception on / [GET] [in /home/train/anaconda2/envs/flask/lib/python2.7/site-packages/flask/app.py:1560]
Traceback (most recent call last):
  File "/home/train/anaconda2/envs/flask/lib/python2.7/site-packages/flask/app.py", line 1982, in wsgi_app
    response = self.full_dispatch_request()
  File "/home/train/anaconda2/envs/flask/lib/python2.7/site-packages/flask/app.py", line 1614, in full_dispatch_request
    rv = self.handle_user_exception(e)
  File "/home/train/anaconda2/envs/flask/lib/python2.7/site-packages/flask/app.py", line 1517, in handle_user_exception
    reraise(exc_type, exc_value, tb)
  File "/home/train/anaconda2/envs/flask/lib/python2.7/site-packages/flask/app.py", line 1610, in full_dispatch_request
    rv = self.preprocess_request()
  File "/home/train/anaconda2/envs/flask/lib/python2.7/site-packages/flask/app.py", line 1831, in preprocess_request
    rv = func()
  File "/media/store/myImplement/my_graduation_paper/obm/app/main/routes.py", line 16, in before_request
    if current_user.is_authenticated:
  File "/home/train/anaconda2/envs/flask/lib/python2.7/site-packages/werkzeug/local.py", line 347, in __getattr__
    return getattr(self._get_current_object(), name)
  File "/home/train/anaconda2/envs/flask/lib/python2.7/site-packages/werkzeug/local.py", line 306, in _get_current_object
    return self.__local()
  File "/home/train/anaconda2/envs/flask/lib/python2.7/site-packages/flask_login/utils.py", line 26, in <lambda>
    current_user = LocalProxy(lambda: _get_user())
  File "/home/train/anaconda2/envs/flask/lib/python2.7/site-packages/flask_login/utils.py", line 302, in _get_user
    current_app.login_manager._load_user()
  File "/home/train/anaconda2/envs/flask/lib/python2.7/site-packages/flask_login/login_manager.py", line 317, in _load_user
    return self.reload_user()
  File "/home/train/anaconda2/envs/flask/lib/python2.7/site-packages/flask_login/login_manager.py", line 279, in reload_user
    user = self.user_callback(user_id)
  File "/media/store/myImplement/my_graduation_paper/obm/app/models.py", line 120, in load_user
    return User.query.get(int(id))
  File "/home/train/anaconda2/envs/flask/lib/python2.7/site-packages/flask_sqlalchemy/__init__.py", line 512, in __get__
    mapper = orm.class_mapper(type)
  File "/home/train/anaconda2/envs/flask/lib/python2.7/site-packages/sqlalchemy/orm/base.py", line 421, in class_mapper
    mapper = _inspect_mapped_class(class_, configure=configure)
  File "/home/train/anaconda2/envs/flask/lib/python2.7/site-packages/sqlalchemy/orm/base.py", line 400, in _inspect_mapped_class
    mapper._configure_all()
  File "/home/train/anaconda2/envs/flask/lib/python2.7/site-packages/sqlalchemy/orm/mapper.py", line 1222, in _configure_all
    configure_mappers()
  File "/home/train/anaconda2/envs/flask/lib/python2.7/site-packages/sqlalchemy/orm/mapper.py", line 2869, in configure_mappers
    raise e
InvalidRequestError: One or more mappers failed to initialize - can't proceed with initialization of other mappers. Triggering mapper: 'Mapper|User|user'. Original exception was: When initializing mapper Mapper|User|user, expression 'Post' failed to locate a name ("name 'Post' is not defined"). If this is a class name, consider adding this relationship() to the <class 'app.models.User'> class after both dependent classes have been defined.
